[2024-03-27T03:54:44.181+0000] {taskinstance.py:1979} INFO - Dependencies all met for dep_context=non-requeueable deps ti=<TaskInstance: Process_W3_Data.create_directories manual__2024-03-27T03:54:41.678731+00:00 [queued]>
[2024-03-27T03:54:44.197+0000] {taskinstance.py:1979} INFO - Dependencies all met for dep_context=requeueable deps ti=<TaskInstance: Process_W3_Data.create_directories manual__2024-03-27T03:54:41.678731+00:00 [queued]>
[2024-03-27T03:54:44.198+0000] {taskinstance.py:2193} INFO - Starting attempt 1 of 1
[2024-03-27T03:54:44.225+0000] {taskinstance.py:2217} INFO - Executing <Task(PythonOperator): create_directories> on 2024-03-27 03:54:41.678731+00:00
[2024-03-27T03:54:44.239+0000] {standard_task_runner.py:60} INFO - Started process 570 to run task
[2024-03-27T03:54:44.246+0000] {standard_task_runner.py:87} INFO - Running: ['***', 'tasks', 'run', 'Process_W3_Data', 'create_directories', 'manual__2024-03-27T03:54:41.678731+00:00', '--job-id', '12', '--raw', '--subdir', 'DAGS_FOLDER/w3c.py', '--cfg-path', '/tmp/tmpa0iab8ed']
[2024-03-27T03:54:44.252+0000] {standard_task_runner.py:88} INFO - Job 12: Subtask create_directories
[2024-03-27T03:54:44.326+0000] {task_command.py:423} INFO - Running <TaskInstance: Process_W3_Data.create_directories manual__2024-03-27T03:54:41.678731+00:00 [running]> on host 94418fe46b42
[2024-03-27T03:54:44.443+0000] {taskinstance.py:2513} INFO - Exporting env vars: AIRFLOW_CTX_DAG_OWNER='***' AIRFLOW_CTX_DAG_ID='Process_W3_Data' AIRFLOW_CTX_TASK_ID='create_directories' AIRFLOW_CTX_EXECUTION_DATE='2024-03-27T03:54:41.678731+00:00' AIRFLOW_CTX_TRY_NUMBER='1' AIRFLOW_CTX_DAG_RUN_ID='manual__2024-03-27T03:54:41.678731+00:00'
[2024-03-27T03:54:44.447+0000] {taskinstance.py:2731} ERROR - Task failed with exception
Traceback (most recent call last):
  File "/home/airflow/.local/lib/python3.8/site-packages/airflow/models/taskinstance.py", line 444, in _execute_task
    result = _execute_callable(context=context, **execute_callable_kwargs)
  File "/home/airflow/.local/lib/python3.8/site-packages/airflow/models/taskinstance.py", line 414, in _execute_callable
    return execute_callable(context=context, **execute_callable_kwargs)
  File "/home/airflow/.local/lib/python3.8/site-packages/airflow/operators/python.py", line 200, in execute
    return_value = self.execute_callable()
  File "/home/airflow/.local/lib/python3.8/site-packages/airflow/operators/python.py", line 217, in execute_callable
    return self.python_callable(*self.op_args, **self.op_kwargs)
  File "/opt/airflow/dags/w3c.py", line 34, in create_dir
    os.mkdir(BaseDir)
FileNotFoundError: [Errno 2] No such file or directory: '/home/airflow/gcs/data'
[2024-03-27T03:54:44.464+0000] {taskinstance.py:1149} INFO - Marking task as FAILED. dag_id=Process_W3_Data, task_id=create_directories, execution_date=20240327T035441, start_date=20240327T035444, end_date=20240327T035444
[2024-03-27T03:54:44.482+0000] {standard_task_runner.py:107} ERROR - Failed to execute job 12 for task create_directories ([Errno 2] No such file or directory: '/home/airflow/gcs/data'; 570)
[2024-03-27T03:54:44.498+0000] {local_task_job_runner.py:234} INFO - Task exited with return code 1
[2024-03-27T03:54:44.524+0000] {taskinstance.py:3312} INFO - 0 downstream tasks scheduled from follow-on schedule check
