[2024-03-27T20:17:31.383+0000] {taskinstance.py:1979} INFO - Dependencies all met for dep_context=non-requeueable deps ti=<TaskInstance: Process_W3_Data.create_directories manual__2024-03-27T20:17:28.618808+00:00 [queued]>
[2024-03-27T20:17:31.394+0000] {taskinstance.py:1979} INFO - Dependencies all met for dep_context=requeueable deps ti=<TaskInstance: Process_W3_Data.create_directories manual__2024-03-27T20:17:28.618808+00:00 [queued]>
[2024-03-27T20:17:31.395+0000] {taskinstance.py:2193} INFO - Starting attempt 1 of 1
[2024-03-27T20:17:31.415+0000] {taskinstance.py:2217} INFO - Executing <Task(PythonOperator): create_directories> on 2024-03-27 20:17:28.618808+00:00
[2024-03-27T20:17:31.425+0000] {standard_task_runner.py:60} INFO - Started process 180 to run task
[2024-03-27T20:17:31.430+0000] {standard_task_runner.py:87} INFO - Running: ['***', 'tasks', 'run', 'Process_W3_Data', 'create_directories', 'manual__2024-03-27T20:17:28.618808+00:00', '--job-id', '5', '--raw', '--subdir', 'DAGS_FOLDER/w3c.py', '--cfg-path', '/tmp/tmpigutn51z']
[2024-03-27T20:17:31.435+0000] {standard_task_runner.py:88} INFO - Job 5: Subtask create_directories
[2024-03-27T20:17:31.508+0000] {task_command.py:423} INFO - Running <TaskInstance: Process_W3_Data.create_directories manual__2024-03-27T20:17:28.618808+00:00 [running]> on host d9bdcddb4bab
[2024-03-27T20:17:31.613+0000] {taskinstance.py:2513} INFO - Exporting env vars: AIRFLOW_CTX_DAG_OWNER='***' AIRFLOW_CTX_DAG_ID='Process_W3_Data' AIRFLOW_CTX_TASK_ID='create_directories' AIRFLOW_CTX_EXECUTION_DATE='2024-03-27T20:17:28.618808+00:00' AIRFLOW_CTX_TRY_NUMBER='1' AIRFLOW_CTX_DAG_RUN_ID='manual__2024-03-27T20:17:28.618808+00:00'
[2024-03-27T20:17:31.616+0000] {logging_mixin.py:188} INFO - Creating directories
[2024-03-27T20:17:31.617+0000] {logging_mixin.py:188} INFO - Current working directory: /opt/***
[2024-03-27T20:17:31.618+0000] {logging_mixin.py:188} INFO - Can't make BaseDir
[2024-03-27T20:17:31.619+0000] {taskinstance.py:2731} ERROR - Task failed with exception
Traceback (most recent call last):
  File "/home/airflow/.local/lib/python3.8/site-packages/airflow/models/taskinstance.py", line 444, in _execute_task
    result = _execute_callable(context=context, **execute_callable_kwargs)
  File "/home/airflow/.local/lib/python3.8/site-packages/airflow/models/taskinstance.py", line 414, in _execute_callable
    return execute_callable(context=context, **execute_callable_kwargs)
  File "/home/airflow/.local/lib/python3.8/site-packages/airflow/operators/python.py", line 200, in execute
    return_value = self.execute_callable()
  File "/home/airflow/.local/lib/python3.8/site-packages/airflow/operators/python.py", line 217, in execute_callable
    return self.python_callable(*self.op_args, **self.op_kwargs)
  File "/opt/airflow/dags/w3c.py", line 47, in CreateDirectory
    os.mkdir(RAW_DATA)
FileNotFoundError: [Errno 2] No such file or directory: '../airflow/data/raw/W3SVC1/'
[2024-03-27T20:17:31.635+0000] {taskinstance.py:1149} INFO - Marking task as FAILED. dag_id=Process_W3_Data, task_id=create_directories, execution_date=20240327T201728, start_date=20240327T201731, end_date=20240327T201731
[2024-03-27T20:17:31.651+0000] {standard_task_runner.py:107} ERROR - Failed to execute job 5 for task create_directories ([Errno 2] No such file or directory: '../airflow/data/raw/W3SVC1/'; 180)
[2024-03-27T20:17:31.684+0000] {local_task_job_runner.py:234} INFO - Task exited with return code 1
[2024-03-27T20:17:31.717+0000] {taskinstance.py:3312} INFO - 0 downstream tasks scheduled from follow-on schedule check
